<?xml version="1.0" encoding="utf-8"?>
<!-- Modularized version of the original Wanren humanoid description. -->
<robot name="wanren_arm" xmlns:xacro="http://www.ros.org/wiki/xacro">
  <xacro:arg name="enable_waist" default="true" />
  <xacro:arg name="enable_neck_left" default="true" />
  <xacro:arg name="enable_neck_right" default="true" />
  <xacro:arg name="enable_arm_left" default="true" />
  <xacro:arg name="enable_arm_right" default="true" />
  <xacro:arg name="enable_leg_left" default="true" />
  <xacro:arg name="enable_leg_right" default="true" />

  <!-- Normalize optional boolean arguments to safe defaults.
       "locals().get" allows the file to be processed even when the
       argument is not provided by older xacro versions that do not
       implicitly register <xacro:arg> values. -->
  <xacro:property name="enable_waist_arg" value="${locals().get('enable_waist', 'true')}" />
  <xacro:property name="enable_waist" value="${str(enable_waist_arg).lower() in ['1', 'true', 'yes']}" />
  <xacro:property name="enable_neck_left_arg" value="${locals().get('enable_neck_left', 'true')}" />
  <xacro:property name="enable_neck_left" value="${str(enable_neck_left_arg).lower() in ['1', 'true', 'yes']}" />
  <xacro:property name="enable_neck_right_arg" value="${locals().get('enable_neck_right', 'true')}" />
  <xacro:property name="enable_neck_right" value="${str(enable_neck_right_arg).lower() in ['1', 'true', 'yes']}" />
  <xacro:property name="enable_arm_left_arg" value="${locals().get('enable_arm_left', 'true')}" />
  <xacro:property name="enable_arm_left" value="${str(enable_arm_left_arg).lower() in ['1', 'true', 'yes']}" />
  <xacro:property name="enable_arm_right_arg" value="${locals().get('enable_arm_right', 'true')}" />
  <xacro:property name="enable_arm_right" value="${str(enable_arm_right_arg).lower() in ['1', 'true', 'yes']}" />
  <xacro:property name="enable_leg_left_arg" value="${locals().get('enable_leg_left', 'true')}" />
  <xacro:property name="enable_leg_left" value="${str(enable_leg_left_arg).lower() in ['1', 'true', 'yes']}" />
  <xacro:property name="enable_leg_right_arg" value="${locals().get('enable_leg_right', 'true')}" />
  <xacro:property name="enable_leg_right" value="${str(enable_leg_right_arg).lower() in ['1', 'true', 'yes']}" />

  <!-- Base reference link -->
  <link name="base_link">
    <inertial>
      <origin xyz="0 0 0" rpy="0 0 0" />
      <mass value="0.001" />
      <inertia ixx="1e-6" ixy="0" ixz="0" iyy="1e-6" iyz="0" izz="1e-6" />
    </inertial>
  </link>

  <xacro:if value="${enable_waist}">
    <link name="waist_link">
      <inertial>
        <origin xyz="0 0 0" rpy="0 0 0" />
        <mass value="0.05" />
        <inertia ixx="1e-4" ixy="0" ixz="0" iyy="1e-4" iyz="0" izz="1e-4" />
      </inertial>
      <visual>
        <origin xyz="0 0 0" rpy="0 0 0" />
        <geometry>
          <cylinder radius="0.08" length="0.05" />
        </geometry>
        <material name="waist_material">
          <color rgba="0.5 0.5 0.5 1" />
        </material>
      </visual>
      <collision>
        <origin xyz="0 0 0" rpy="0 0 0" />
        <geometry>
          <cylinder radius="0.08" length="0.05" />
        </geometry>
      </collision>
    </link>

    <joint name="waist_yaw_joint" type="continuous">
      <origin xyz="0 0 0" rpy="0 0 0" />
      <parent link="base_link" />
      <child link="waist_link" />
      <axis xyz="0 0 1" />
    </joint>

    <joint name="waist_to_torso_fixed" type="fixed">
      <origin xyz="0 0 0" rpy="0 0 0" />
      <parent link="waist_link" />
      <child link="torso_link" />
    </joint>
  </xacro:if>

  <xacro:unless value="${enable_waist}">
    <joint name="base_to_torso_fixed" type="fixed">
      <origin xyz="0 0 0" rpy="0 0 0" />
      <parent link="base_link" />
      <child link="torso_link" />
    </joint>
  </xacro:unless>

  <!-- Add a dummy link to handle inertia -->
  <link
    name="torso_link">
    <inertial>
      <origin
        xyz="1.58624299813302E-05 2.01332320114156E-07 -0.0245724500252954"
        rpy="0 0 0" />
      <mass
        value="0.60016209200883" />
      <inertia
        ixx="0.00242953311427902"
        ixy="-5.25284926483854E-09"
        ixz="-1.0307989110718E-08"
        iyy="0.000676060412175399"
        iyz="-4.23866154122213E-09"
        izz="0.00270966081437587" />
    </inertial>
    <visual>
      <origin
        xyz="0 0 0"
        rpy="0 0 0" />
      <geometry>
        <mesh
          filename="package://wanren_arm/meshes/body.STL" />
      </geometry>
      <material
        name="">
        <color
          rgba="1 1 1 1" />
      </material>
    </visual>
    <collision>
      <origin
        xyz="0 0 0"
        rpy="0 0 0" />
      <geometry>
        <mesh
          filename="package://wanren_arm/meshes/body.STL" />
      </geometry>
    </collision>
  </link>
  <xacro:if value="${enable_leg_right}">
  <link
    name="leg_right_link_1">
    <inertial>
      <origin
        xyz="-0.00382422792815949 -0.0123142355221975 0.0766747228132015"
        rpy="0 0 0" />
      <mass
        value="0.292899916417866" />
      <inertia
        ixx="0.000252199489311626"
        ixy="1.84502350325129E-05"
        ixz="3.06532558789357E-06"
        iyy="0.000305653266020346"
        iyz="9.64612915614931E-06"
        izz="0.000181236852257132" />
    </inertial>
    <visual>
      <origin
        xyz="0 0 0"
        rpy="0 0 0" />
      <geometry>
        <mesh
          filename="package://wanren_arm/meshes/leg_r1.STL" />
      </geometry>
      <material
        name="">
        <color
          rgba="1 1 1 1" />
      </material>
    </visual>
    <collision>
      <origin
        xyz="0 0 0"
        rpy="0 0 0" />
      <geometry>
        <mesh
          filename="package://wanren_arm/meshes/leg_r1.STL" />
      </geometry>
    </collision>
  </link>
  <joint
    name="leg_right_joint_1"
    type="continuous">
    <origin
      xyz="0 0 0.011999999999999"
      rpy="0 0 0" />
    <parent
      link="torso_link" />
    <child
      link="leg_right_link_1" />
    <axis
      xyz="0 0 -1" />
  </joint>
  <link
    name="leg_right_link_2">
    <inertial>
      <origin
        xyz="0.0284932164900757 0.0852314382000906 0.0233442478183801"
        rpy="0 0 0" />
      <mass
        value="0.118782011304387" />
      <inertia
        ixx="0.000148335029284927"
        ixy="-8.65175116738488E-06"
        ixz="-1.27967801985177E-05"
        iyy="0.000134918605784322"
        iyz="-4.16906433393106E-05"
        izz="0.000154509301437256" />
    </inertial>
    <visual>
      <origin
        xyz="0 0 0"
        rpy="0 0 0" />
      <geometry>
        <mesh
          filename="package://wanren_arm/meshes/leg_r2.STL" />
      </geometry>
      <material
        name="">
        <color
          rgba="1 1 1 1" />
      </material>
    </visual>
    <collision>
      <origin
        xyz="0 0 0"
        rpy="0 0 0" />
      <geometry>
        <mesh
          filename="package://wanren_arm/meshes/leg_r2.STL" />
      </geometry>
    </collision>
  </link>
  <joint
    name="leg_right_joint_2"
    type="continuous">
    <origin
      xyz="-0.0136812977041495 -0.0436944371355362 0.0808116620061236"
      rpy="0 0 0" />
    <parent
      link="leg_right_link_1" />
    <child
      link="leg_right_link_2" />
    <axis
      xyz="0.29752487908452 0.954714065218347 0" />
  </joint>
  <link
    name="leg_right_link_3">
    <inertial>
      <origin
        xyz="0.00440804925886197 -0.000927955750798931 0.0105438054247052"
        rpy="0 0 0" />
      <mass
        value="0.395227613542105" />
      <inertia
        ixx="0.000308890320718613"
        ixy="-5.97376048863321E-06"
        ixz="-4.28271122717806E-07"
        iyy="0.000290511069752979"
        iyz="-7.01321630599807E-06"
        izz="0.000217174460223541" />
    </inertial>
    <visual>
      <origin
        xyz="0 0 0"
        rpy="0 0 0" />
      <geometry>
        <mesh
          filename="package://wanren_arm/meshes/leg_r3.STL" />
      </geometry>
      <material
        name="">
        <color
          rgba="0.752941176470588 0.752941176470588 0.752941176470588 1" />
      </material>
    </visual>
    <collision>
      <origin
        xyz="0 0 0"
        rpy="0 0 0" />
      <geometry>
        <mesh
          filename="package://wanren_arm/meshes/leg_r3.STL" />
      </geometry>
    </collision>
  </link>
  <joint
    name="leg_right_joint_3"
    type="continuous">
    <origin
      xyz="0.0412068272569313 0.104588881771451 0.106228185949221"
      rpy="0 0 0" />
    <parent
      link="leg_right_link_2" />
    <child
      link="leg_right_link_3" />
    <axis
      xyz="-0.0722349306802614 0.022511126419206 -0.997133573788866" />
  </joint>
  <link
    name="leg_right_link_4">
    <inertial>
      <origin
        xyz="0.0155060558890136 0.0411774297341984 0.0346709586399187"
        rpy="0 0 0" />
      <mass
        value="0.0222841339329651" />
      <inertia
        ixx="1.84809601603307E-05"
        ixy="-7.49503824125524E-07"
        ixz="7.29303214418526E-07"
        iyy="1.42244264185631E-05"
        iyz="5.6744596945616E-06"
        izz="8.89285098125665E-06" />
    </inertial>
    <visual>
      <origin
        xyz="0 0 0"
        rpy="0 0 0" />
      <geometry>
        <mesh
          filename="package://wanren_arm/meshes/leg_r4.STL" />
      </geometry>
      <material
        name="">
        <color
          rgba="1 1 1 1" />
      </material>
    </visual>
    <collision>
      <origin
        xyz="0 0 0"
        rpy="0 0 0" />
      <geometry>
        <mesh
          filename="package://wanren_arm/meshes/leg_r4.STL" />
      </geometry>
    </collision>
  </link>
  <joint
    name="leg_right_joint_4"
    type="continuous">
    <origin
      xyz="-0.00228042956033238 -0.0297792321778995 0.0833604475054363"
      rpy="0 0 0" />
    <parent
      link="leg_right_link_3" />
    <child
      link="leg_right_link_4" />
    <axis
      xyz="0.282983296167026 0.959124144572578 0.0011529910516605" />
  </joint>
  <link
    name="leg_right_link_5">
    <inertial>
      <origin
        xyz="-0.0048559147531092 -0.0119363039004067 -0.00678188706287566"
        rpy="0 0 0" />
      <mass
        value="0.38824624930896" />
      <inertia
        ixx="0.000237526648339387"
        ixy="-5.31429070295641E-05"
        ixz="2.19325891659962E-05"
        iyy="0.000363875907133575"
        iyz="1.18765086359219E-05"
        izz="0.000378463701930693" />
    </inertial>
    <visual>
      <origin
        xyz="0 0 0"
        rpy="0 0 0" />
      <geometry>
        <mesh
          filename="package://wanren_arm/meshes/leg_r5.STL" />
      </geometry>
      <material
        name="">
        <color
          rgba="0.752941176470588 0.752941176470588 0.752941176470588 1" />
      </material>
    </visual>
    <collision>
      <origin
        xyz="0 0 0"
        rpy="0 0 0" />
      <geometry>
        <mesh
          filename="package://wanren_arm/meshes/leg_r5.STL" />
      </geometry>
    </collision>
  </link>
  <joint
    name="leg_right_joint_5"
    type="continuous">
    <origin
      xyz="0.0181511434262854 0.025007599076044 0.111134888878763"
      rpy="0 1.26722046551249 0" />
    <parent
      link="leg_right_link_4" />
    <child
      link="leg_right_link_5" />
    <axis
      xyz="0.923719785557326 0.0273056458564005 -0.382094437900229" />
  </joint>
  <link
    name="leg_right_link_6">
    <inertial>
      <origin
        xyz="0.0651691107467127 0.0806102275858783 -0.0545046281847596"
        rpy="0 0 0" />
      <mass
        value="0.174871084341935" />
      <inertia
        ixx="0.000144391761957596"
        ixy="-1.80182197600083E-05"
        ixz="1.3262109156489E-05"
        iyy="7.06944905975503E-05"
        iyz="1.59148040690902E-05"
        izz="0.000136401918690474" />
    </inertial>
    <visual>
      <origin
        xyz="0 0 0"
        rpy="0 0 0" />
      <geometry>
        <mesh
          filename="package://wanren_arm/meshes/leg_r6.STL" />
      </geometry>
      <material
        name="">
        <color
          rgba="1 1 1 1" />
      </material>
    </visual>
    <collision>
      <origin
        xyz="0 0 0"
        rpy="0 0 0" />
      <geometry>
        <mesh
          filename="package://wanren_arm/meshes/leg_r6.STL" />
      </geometry>
    </collision>
  </link>
  <joint
    name="leg_right_joint_6"
    type="continuous">
    <origin
      xyz="-0.0550712045826083 -0.0332459772838745 -0.000878918231283499"
      rpy="1.5372364468678 -1.26722046551249 0" />
    <parent
      link="leg_right_link_5" />
    <child
      link="leg_right_link_6" />
    <axis
      xyz="0.565655964466871 0 -0.824641334073823" />
  </joint>
  <link
    name="leg_right_link_7">
    <inertial>
      <origin
        xyz="0.122014637753753 -0.108460665221082 -0.0505526819127103"
        rpy="0 0 0" />
      <mass
        value="0.784412251530751" />
      <inertia
        ixx="0.00035684591190941"
        ixy="5.28938521033195E-05"
        ixz="1.61063033449861E-05"
        iyy="0.000393694186319801"
        iyz="-3.02303341596539E-06"
        izz="0.000403461621026228" />
    </inertial>
    <visual>
      <origin xyz="0 0 0" rpy="0 0 0"/>
  	<geometry>
    	<box size="0.1 0.05 0.04"/>
  	</geometry>
    </visual>
    <collision>
  	<origin xyz="0 0 0" rpy="0 0 0"/>
  	<geometry>
    	<box size="0.1 0.05 0.04"/>
  	</geometry>
    </collision>
  </link>
  <joint
    name="leg_right_joint_7"
    type="continuous">
    <origin
      xyz="0.0506954674848457 0.0975609362242854 -0.0679978120533321"
      rpy="-1.5372364468678 0 0" />
    <parent
      link="leg_right_link_6" />
    <child
      link="leg_right_link_7" />
    <axis
      xyz="0.804819794366103 -0.559061164385712 -0.199288015375224" />
  </joint>


  <!-- Added neck and arm kinematics -->
  <xacro:if value="${enable_neck_left or enable_neck_right}">
  <!-- Neck base -->
  <link name="neck_mount_link">
    <inertial>
      <origin xyz="0 0 0" rpy="0 0 0"/>
      <mass value="0.200"/>
      <inertia ixx="0.000600" ixy="0" ixz="0" iyy="0.000600" iyz="0" izz="0.000600"/>
    </inertial>
    <visual>
      <origin xyz="0 0 0" rpy="0 0 0"/>
      <geometry>
        <sphere radius="0.050"/>
      </geometry>
      <material name="neck_mount">
        <color rgba="0.4 0.4 0.4 1"/>
      </material>
    </visual>
    <collision>
      <origin xyz="0 0 0" rpy="0 0 0"/>
      <geometry>
        <sphere radius="0.050"/>
      </geometry>
    </collision>
  </link>
  <joint name="neck_mount_fixed" type="fixed">
    <origin xyz="0 0 0.45" rpy="0 0 0"/>
    <parent link="torso_link"/>
    <child link="neck_mount_link"/>
  </joint>
  <xacro:if value="${enable_neck_left}">
  <link name="neck_left_link_1">
    <inertial>
      <origin xyz="0 0 0.040" rpy="0 0 0"/>
      <mass value="0.080"/>
      <inertia ixx="0.000043" ixy="0" ixz="0" iyy="0.000043" iyz="0" izz="0.000016"/>
    </inertial>
    <visual>
      <origin xyz="0 0 0.040" rpy="0 0 0"/>
      <geometry>
        <cylinder radius="0.020" length="0.080"/>
      </geometry>
      <material name="aluminum">
        <color rgba="0.7 0.7 0.7 1"/>
      </material>
    </visual>
    <collision>
      <origin xyz="0 0 0.040" rpy="0 0 0"/>
      <geometry>
        <cylinder radius="0.020" length="0.080"/>
      </geometry>
    </collision>
  </link>
  <link name="neck_left_link_2">
    <inertial>
      <origin xyz="0 0 0.040" rpy="0 0 0"/>
      <mass value="0.080"/>
      <inertia ixx="0.000043" ixy="0" ixz="0" iyy="0.000043" iyz="0" izz="0.000016"/>
    </inertial>
    <visual>
      <origin xyz="0 0 0.040" rpy="0 0 0"/>
      <geometry>
        <cylinder radius="0.020" length="0.080"/>
      </geometry>
      <material name="aluminum">
        <color rgba="0.7 0.7 0.7 1"/>
      </material>
    </visual>
    <collision>
      <origin xyz="0 0 0.040" rpy="0 0 0"/>
      <geometry>
        <cylinder radius="0.020" length="0.080"/>
      </geometry>
    </collision>
  </link>
  <link name="neck_left_link_3">
    <inertial>
      <origin xyz="0 0 0.040" rpy="0 0 0"/>
      <mass value="0.080"/>
      <inertia ixx="0.000043" ixy="0" ixz="0" iyy="0.000043" iyz="0" izz="0.000016"/>
    </inertial>
    <visual>
      <origin xyz="0 0 0.040" rpy="0 0 0"/>
      <geometry>
        <cylinder radius="0.020" length="0.080"/>
      </geometry>
      <material name="aluminum">
        <color rgba="0.7 0.7 0.7 1"/>
      </material>
    </visual>
    <collision>
      <origin xyz="0 0 0.040" rpy="0 0 0"/>
      <geometry>
        <cylinder radius="0.020" length="0.080"/>
      </geometry>
    </collision>
  </link>
  <link name="neck_left_link_4">
    <inertial>
      <origin xyz="0 0 0.040" rpy="0 0 0"/>
      <mass value="0.080"/>
      <inertia ixx="0.000043" ixy="0" ixz="0" iyy="0.000043" iyz="0" izz="0.000016"/>
    </inertial>
    <visual>
      <origin xyz="0 0 0.040" rpy="0 0 0"/>
      <geometry>
        <cylinder radius="0.020" length="0.080"/>
      </geometry>
      <material name="aluminum">
        <color rgba="0.7 0.7 0.7 1"/>
      </material>
    </visual>
    <collision>
      <origin xyz="0 0 0.040" rpy="0 0 0"/>
      <geometry>
        <cylinder radius="0.020" length="0.080"/>
      </geometry>
    </collision>
  </link>
  <link name="neck_left_link_5">
    <inertial>
      <origin xyz="0 0 0.040" rpy="0 0 0"/>
      <mass value="0.080"/>
      <inertia ixx="0.000043" ixy="0" ixz="0" iyy="0.000043" iyz="0" izz="0.000016"/>
    </inertial>
    <visual>
      <origin xyz="0 0 0.040" rpy="0 0 0"/>
      <geometry>
        <cylinder radius="0.020" length="0.080"/>
      </geometry>
      <material name="aluminum">
        <color rgba="0.7 0.7 0.7 1"/>
      </material>
    </visual>
    <collision>
      <origin xyz="0 0 0.040" rpy="0 0 0"/>
      <geometry>
        <cylinder radius="0.020" length="0.080"/>
      </geometry>
    </collision>
  </link>
  <link name="neck_left_link_6">
    <inertial>
      <origin xyz="0 0 0.040" rpy="0 0 0"/>
      <mass value="0.080"/>
      <inertia ixx="0.000043" ixy="0" ixz="0" iyy="0.000043" iyz="0" izz="0.000016"/>
    </inertial>
    <visual>
      <origin xyz="0 0 0.040" rpy="0 0 0"/>
      <geometry>
        <cylinder radius="0.020" length="0.080"/>
      </geometry>
      <material name="aluminum">
        <color rgba="0.7 0.7 0.7 1"/>
      </material>
    </visual>
    <collision>
      <origin xyz="0 0 0.040" rpy="0 0 0"/>
      <geometry>
        <cylinder radius="0.020" length="0.080"/>
      </geometry>
    </collision>
  </link>
  <link name="neck_left_link_7">
    <inertial>
      <origin xyz="0 0 0.040" rpy="0 0 0"/>
      <mass value="0.080"/>
      <inertia ixx="0.000043" ixy="0" ixz="0" iyy="0.000043" iyz="0" izz="0.000016"/>
    </inertial>
    <visual>
      <origin xyz="0 0 0.040" rpy="0 0 0"/>
      <geometry>
        <cylinder radius="0.020" length="0.080"/>
      </geometry>
      <material name="aluminum">
        <color rgba="0.7 0.7 0.7 1"/>
      </material>
    </visual>
    <collision>
      <origin xyz="0 0 0.040" rpy="0 0 0"/>
      <geometry>
        <cylinder radius="0.020" length="0.080"/>
      </geometry>
    </collision>
  </link>
  <joint name="neck_left_joint_1" type="continuous">
    <origin xyz="0.000 0.060 0.000" rpy="0 0 0"/>
    <parent link="neck_mount_link"/>
    <child link="neck_left_link_1"/>
    <axis xyz="0 0 1"/>
  </joint>
  <joint name="neck_left_joint_2" type="continuous">
    <origin xyz="0.000 0.000 0.080" rpy="0 0 0"/>
    <parent link="neck_left_link_1"/>
    <child link="neck_left_link_2"/>
    <axis xyz="0 1 0"/>
  </joint>
  <joint name="neck_left_joint_3" type="continuous">
    <origin xyz="0.000 0.000 0.080" rpy="0 0 0"/>
    <parent link="neck_left_link_2"/>
    <child link="neck_left_link_3"/>
    <axis xyz="1 0 0"/>
  </joint>
  <joint name="neck_left_joint_4" type="continuous">
    <origin xyz="0.000 0.000 0.080" rpy="0 0 0"/>
    <parent link="neck_left_link_3"/>
    <child link="neck_left_link_4"/>
    <axis xyz="0 1 0"/>
  </joint>
  <joint name="neck_left_joint_5" type="continuous">
    <origin xyz="0.000 0.000 0.080" rpy="0 0 0"/>
    <parent link="neck_left_link_4"/>
    <child link="neck_left_link_5"/>
    <axis xyz="1 0 0"/>
  </joint>
  <joint name="neck_left_joint_6" type="continuous">
    <origin xyz="0.000 0.000 0.080" rpy="0 0 0"/>
    <parent link="neck_left_link_5"/>
    <child link="neck_left_link_6"/>
    <axis xyz="0 1 0"/>
  </joint>
  <joint name="neck_left_joint_7" type="continuous">
    <origin xyz="0.000 0.000 0.080" rpy="0 0 0"/>
    <parent link="neck_left_link_6"/>
    <child link="neck_left_link_7"/>
    <axis xyz="1 0 0"/>
  </joint>
  <xacro:if value="${enable_neck_right}">
  <link name="neck_right_link_1">
    <inertial>
      <origin xyz="0 0 0.040" rpy="0 0 0"/>
      <mass value="0.080"/>
      <inertia ixx="0.000043" ixy="0" ixz="0" iyy="0.000043" iyz="0" izz="0.000016"/>
    </inertial>
    <visual>
      <origin xyz="0 0 0.040" rpy="0 0 0"/>
      <geometry>
        <cylinder radius="0.020" length="0.080"/>
      </geometry>
      <material name="aluminum">
        <color rgba="0.7 0.7 0.7 1"/>
      </material>
    </visual>
    <collision>
      <origin xyz="0 0 0.040" rpy="0 0 0"/>
      <geometry>
        <cylinder radius="0.020" length="0.080"/>
      </geometry>
    </collision>
  </link>
  <link name="neck_right_link_2">
    <inertial>
      <origin xyz="0 0 0.040" rpy="0 0 0"/>
      <mass value="0.080"/>
      <inertia ixx="0.000043" ixy="0" ixz="0" iyy="0.000043" iyz="0" izz="0.000016"/>
    </inertial>
    <visual>
      <origin xyz="0 0 0.040" rpy="0 0 0"/>
      <geometry>
        <cylinder radius="0.020" length="0.080"/>
      </geometry>
      <material name="aluminum">
        <color rgba="0.7 0.7 0.7 1"/>
      </material>
    </visual>
    <collision>
      <origin xyz="0 0 0.040" rpy="0 0 0"/>
      <geometry>
        <cylinder radius="0.020" length="0.080"/>
      </geometry>
    </collision>
  </link>
  <link name="neck_right_link_3">
    <inertial>
      <origin xyz="0 0 0.040" rpy="0 0 0"/>
      <mass value="0.080"/>
      <inertia ixx="0.000043" ixy="0" ixz="0" iyy="0.000043" iyz="0" izz="0.000016"/>
    </inertial>
    <visual>
      <origin xyz="0 0 0.040" rpy="0 0 0"/>
      <geometry>
        <cylinder radius="0.020" length="0.080"/>
      </geometry>
      <material name="aluminum">
        <color rgba="0.7 0.7 0.7 1"/>
      </material>
    </visual>
    <collision>
      <origin xyz="0 0 0.040" rpy="0 0 0"/>
      <geometry>
        <cylinder radius="0.020" length="0.080"/>
      </geometry>
    </collision>
  </link>
  <link name="neck_right_link_4">
    <inertial>
      <origin xyz="0 0 0.040" rpy="0 0 0"/>
      <mass value="0.080"/>
      <inertia ixx="0.000043" ixy="0" ixz="0" iyy="0.000043" iyz="0" izz="0.000016"/>
    </inertial>
    <visual>
      <origin xyz="0 0 0.040" rpy="0 0 0"/>
      <geometry>
        <cylinder radius="0.020" length="0.080"/>
      </geometry>
      <material name="aluminum">
        <color rgba="0.7 0.7 0.7 1"/>
      </material>
    </visual>
    <collision>
      <origin xyz="0 0 0.040" rpy="0 0 0"/>
      <geometry>
        <cylinder radius="0.020" length="0.080"/>
      </geometry>
    </collision>
  </link>
  <link name="neck_right_link_5">
    <inertial>
      <origin xyz="0 0 0.040" rpy="0 0 0"/>
      <mass value="0.080"/>
      <inertia ixx="0.000043" ixy="0" ixz="0" iyy="0.000043" iyz="0" izz="0.000016"/>
    </inertial>
    <visual>
      <origin xyz="0 0 0.040" rpy="0 0 0"/>
      <geometry>
        <cylinder radius="0.020" length="0.080"/>
      </geometry>
      <material name="aluminum">
        <color rgba="0.7 0.7 0.7 1"/>
      </material>
    </visual>
    <collision>
      <origin xyz="0 0 0.040" rpy="0 0 0"/>
      <geometry>
        <cylinder radius="0.020" length="0.080"/>
      </geometry>
    </collision>
  </link>
  <link name="neck_right_link_6">
    <inertial>
      <origin xyz="0 0 0.040" rpy="0 0 0"/>
      <mass value="0.080"/>
      <inertia ixx="0.000043" ixy="0" ixz="0" iyy="0.000043" iyz="0" izz="0.000016"/>
    </inertial>
    <visual>
      <origin xyz="0 0 0.040" rpy="0 0 0"/>
      <geometry>
        <cylinder radius="0.020" length="0.080"/>
      </geometry>
      <material name="aluminum">
        <color rgba="0.7 0.7 0.7 1"/>
      </material>
    </visual>
    <collision>
      <origin xyz="0 0 0.040" rpy="0 0 0"/>
      <geometry>
        <cylinder radius="0.020" length="0.080"/>
      </geometry>
    </collision>
  </link>
  <link name="neck_right_link_7">
    <inertial>
      <origin xyz="0 0 0.040" rpy="0 0 0"/>
      <mass value="0.080"/>
      <inertia ixx="0.000043" ixy="0" ixz="0" iyy="0.000043" iyz="0" izz="0.000016"/>
    </inertial>
    <visual>
      <origin xyz="0 0 0.040" rpy="0 0 0"/>
      <geometry>
        <cylinder radius="0.020" length="0.080"/>
      </geometry>
      <material name="aluminum">
        <color rgba="0.7 0.7 0.7 1"/>
      </material>
    </visual>
    <collision>
      <origin xyz="0 0 0.040" rpy="0 0 0"/>
      <geometry>
        <cylinder radius="0.020" length="0.080"/>
      </geometry>
    </collision>
  </link>
  <joint name="neck_right_joint_1" type="continuous">
    <origin xyz="0.000 -0.060 0.000" rpy="0 0 0"/>
    <parent link="neck_mount_link"/>
    <child link="neck_right_link_1"/>
    <axis xyz="0 0 1"/>
  </joint>
  <joint name="neck_right_joint_2" type="continuous">
    <origin xyz="0.000 0.000 0.080" rpy="0 0 0"/>
    <parent link="neck_right_link_1"/>
    <child link="neck_right_link_2"/>
    <axis xyz="0 1 0"/>
  </joint>
  <joint name="neck_right_joint_3" type="continuous">
    <origin xyz="0.000 0.000 0.080" rpy="0 0 0"/>
    <parent link="neck_right_link_2"/>
    <child link="neck_right_link_3"/>
    <axis xyz="1 0 0"/>
  </joint>
  <joint name="neck_right_joint_4" type="continuous">
    <origin xyz="0.000 0.000 0.080" rpy="0 0 0"/>
    <parent link="neck_right_link_3"/>
    <child link="neck_right_link_4"/>
    <axis xyz="0 1 0"/>
  </joint>
  <joint name="neck_right_joint_5" type="continuous">
    <origin xyz="0.000 0.000 0.080" rpy="0 0 0"/>
    <parent link="neck_right_link_4"/>
    <child link="neck_right_link_5"/>
    <axis xyz="1 0 0"/>
  </joint>
  <joint name="neck_right_joint_6" type="continuous">
    <origin xyz="0.000 0.000 0.080" rpy="0 0 0"/>
    <parent link="neck_right_link_5"/>
    <child link="neck_right_link_6"/>
    <axis xyz="0 1 0"/>
  </joint>
  <joint name="neck_right_joint_7" type="continuous">
    <origin xyz="0.000 0.000 0.080" rpy="0 0 0"/>
    <parent link="neck_right_link_6"/>
    <child link="neck_right_link_7"/>
    <axis xyz="1 0 0"/>
  </joint>
  <xacro:if value="${enable_arm_left}">
  <link name="arm_left_link_1">
    <inertial>
      <origin xyz="0 0 0.090" rpy="0 0 0"/>
      <mass value="0.120"/>
      <inertia ixx="0.000324" ixy="0" ixz="0" iyy="0.000324" iyz="0" izz="0.000038"/>
    </inertial>
    <visual>
      <origin xyz="0 0 0.090" rpy="0 0 0"/>
      <geometry>
        <cylinder radius="0.025" length="0.180"/>
      </geometry>
      <material name="aluminum">
        <color rgba="0.7 0.7 0.7 1"/>
      </material>
    </visual>
    <collision>
      <origin xyz="0 0 0.090" rpy="0 0 0"/>
      <geometry>
        <cylinder radius="0.025" length="0.180"/>
      </geometry>
    </collision>
  </link>
  <link name="arm_left_link_2">
    <inertial>
      <origin xyz="0 0 0.090" rpy="0 0 0"/>
      <mass value="0.120"/>
      <inertia ixx="0.000324" ixy="0" ixz="0" iyy="0.000324" iyz="0" izz="0.000038"/>
    </inertial>
    <visual>
      <origin xyz="0 0 0.090" rpy="0 0 0"/>
      <geometry>
        <cylinder radius="0.025" length="0.180"/>
      </geometry>
      <material name="aluminum">
        <color rgba="0.7 0.7 0.7 1"/>
      </material>
    </visual>
    <collision>
      <origin xyz="0 0 0.090" rpy="0 0 0"/>
      <geometry>
        <cylinder radius="0.025" length="0.180"/>
      </geometry>
    </collision>
  </link>
  <link name="arm_left_link_3">
    <inertial>
      <origin xyz="0 0 0.090" rpy="0 0 0"/>
      <mass value="0.120"/>
      <inertia ixx="0.000324" ixy="0" ixz="0" iyy="0.000324" iyz="0" izz="0.000038"/>
    </inertial>
    <visual>
      <origin xyz="0 0 0.090" rpy="0 0 0"/>
      <geometry>
        <cylinder radius="0.025" length="0.180"/>
      </geometry>
      <material name="aluminum">
        <color rgba="0.7 0.7 0.7 1"/>
      </material>
    </visual>
    <collision>
      <origin xyz="0 0 0.090" rpy="0 0 0"/>
      <geometry>
        <cylinder radius="0.025" length="0.180"/>
      </geometry>
    </collision>
  </link>
  <link name="arm_left_link_4">
    <inertial>
      <origin xyz="0 0 0.090" rpy="0 0 0"/>
      <mass value="0.120"/>
      <inertia ixx="0.000324" ixy="0" ixz="0" iyy="0.000324" iyz="0" izz="0.000038"/>
    </inertial>
    <visual>
      <origin xyz="0 0 0.090" rpy="0 0 0"/>
      <geometry>
        <cylinder radius="0.025" length="0.180"/>
      </geometry>
      <material name="aluminum">
        <color rgba="0.7 0.7 0.7 1"/>
      </material>
    </visual>
    <collision>
      <origin xyz="0 0 0.090" rpy="0 0 0"/>
      <geometry>
        <cylinder radius="0.025" length="0.180"/>
      </geometry>
    </collision>
  </link>
  <link name="arm_left_link_5">
    <inertial>
      <origin xyz="0 0 0.090" rpy="0 0 0"/>
      <mass value="0.120"/>
      <inertia ixx="0.000324" ixy="0" ixz="0" iyy="0.000324" iyz="0" izz="0.000038"/>
    </inertial>
    <visual>
      <origin xyz="0 0 0.090" rpy="0 0 0"/>
      <geometry>
        <cylinder radius="0.025" length="0.180"/>
      </geometry>
      <material name="aluminum">
        <color rgba="0.7 0.7 0.7 1"/>
      </material>
    </visual>
    <collision>
      <origin xyz="0 0 0.090" rpy="0 0 0"/>
      <geometry>
        <cylinder radius="0.025" length="0.180"/>
      </geometry>
    </collision>
  </link>
  <link name="arm_left_link_6">
    <inertial>
      <origin xyz="0 0 0.090" rpy="0 0 0"/>
      <mass value="0.120"/>
      <inertia ixx="0.000324" ixy="0" ixz="0" iyy="0.000324" iyz="0" izz="0.000038"/>
    </inertial>
    <visual>
      <origin xyz="0 0 0.090" rpy="0 0 0"/>
      <geometry>
        <cylinder radius="0.025" length="0.180"/>
      </geometry>
      <material name="aluminum">
        <color rgba="0.7 0.7 0.7 1"/>
      </material>
    </visual>
    <collision>
      <origin xyz="0 0 0.090" rpy="0 0 0"/>
      <geometry>
        <cylinder radius="0.025" length="0.180"/>
      </geometry>
    </collision>
  </link>
  <link name="arm_left_link_7">
    <inertial>
      <origin xyz="0 0 0.090" rpy="0 0 0"/>
      <mass value="0.120"/>
      <inertia ixx="0.000324" ixy="0" ixz="0" iyy="0.000324" iyz="0" izz="0.000038"/>
    </inertial>
    <visual>
      <origin xyz="0 0 0.090" rpy="0 0 0"/>
      <geometry>
        <cylinder radius="0.025" length="0.180"/>
      </geometry>
      <material name="aluminum">
        <color rgba="0.7 0.7 0.7 1"/>
      </material>
    </visual>
    <collision>
      <origin xyz="0 0 0.090" rpy="0 0 0"/>
      <geometry>
        <cylinder radius="0.025" length="0.180"/>
      </geometry>
    </collision>
  </link>
  <joint name="arm_left_joint_1" type="continuous">
    <origin xyz="0.050 0.250 0.250" rpy="0 0 0"/>
    <parent link="torso_link"/>
    <child link="arm_left_link_1"/>
    <axis xyz="0 0 1"/>
  </joint>
  <joint name="arm_left_joint_2" type="continuous">
    <origin xyz="0.000 0.000 0.180" rpy="0 0 0"/>
    <parent link="arm_left_link_1"/>
    <child link="arm_left_link_2"/>
    <axis xyz="0 1 0"/>
  </joint>
  <joint name="arm_left_joint_3" type="continuous">
    <origin xyz="0.000 0.000 0.180" rpy="0 0 0"/>
    <parent link="arm_left_link_2"/>
    <child link="arm_left_link_3"/>
    <axis xyz="0 1 0"/>
  </joint>
  <joint name="arm_left_joint_4" type="continuous">
    <origin xyz="0.000 0.000 0.180" rpy="0 0 0"/>
    <parent link="arm_left_link_3"/>
    <child link="arm_left_link_4"/>
    <axis xyz="1 0 0"/>
  </joint>
  <joint name="arm_left_joint_5" type="continuous">
    <origin xyz="0.000 0.000 0.180" rpy="0 0 0"/>
    <parent link="arm_left_link_4"/>
    <child link="arm_left_link_5"/>
    <axis xyz="0 1 0"/>
  </joint>
  <joint name="arm_left_joint_6" type="continuous">
    <origin xyz="0.000 0.000 0.180" rpy="0 0 0"/>
    <parent link="arm_left_link_5"/>
    <child link="arm_left_link_6"/>
    <axis xyz="1 0 0"/>
  </joint>
  <joint name="arm_left_joint_7" type="continuous">
    <origin xyz="0.000 0.000 0.180" rpy="0 0 0"/>
    <parent link="arm_left_link_6"/>
    <child link="arm_left_link_7"/>
    <axis xyz="0 1 0"/>
  </joint>
  <xacro:if value="${enable_arm_right}">
  <link name="arm_right_link_1">
    <inertial>
      <origin xyz="0 0 0.090" rpy="0 0 0"/>
      <mass value="0.120"/>
      <inertia ixx="0.000324" ixy="0" ixz="0" iyy="0.000324" iyz="0" izz="0.000038"/>
    </inertial>
    <visual>
      <origin xyz="0 0 0.090" rpy="0 0 0"/>
      <geometry>
        <cylinder radius="0.025" length="0.180"/>
      </geometry>
      <material name="aluminum">
        <color rgba="0.7 0.7 0.7 1"/>
      </material>
    </visual>
    <collision>
      <origin xyz="0 0 0.090" rpy="0 0 0"/>
      <geometry>
        <cylinder radius="0.025" length="0.180"/>
      </geometry>
    </collision>
  </link>
  <link name="arm_right_link_2">
    <inertial>
      <origin xyz="0 0 0.090" rpy="0 0 0"/>
      <mass value="0.120"/>
      <inertia ixx="0.000324" ixy="0" ixz="0" iyy="0.000324" iyz="0" izz="0.000038"/>
    </inertial>
    <visual>
      <origin xyz="0 0 0.090" rpy="0 0 0"/>
      <geometry>
        <cylinder radius="0.025" length="0.180"/>
      </geometry>
      <material name="aluminum">
        <color rgba="0.7 0.7 0.7 1"/>
      </material>
    </visual>
    <collision>
      <origin xyz="0 0 0.090" rpy="0 0 0"/>
      <geometry>
        <cylinder radius="0.025" length="0.180"/>
      </geometry>
    </collision>
  </link>
  <link name="arm_right_link_3">
    <inertial>
      <origin xyz="0 0 0.090" rpy="0 0 0"/>
      <mass value="0.120"/>
      <inertia ixx="0.000324" ixy="0" ixz="0" iyy="0.000324" iyz="0" izz="0.000038"/>
    </inertial>
    <visual>
      <origin xyz="0 0 0.090" rpy="0 0 0"/>
      <geometry>
        <cylinder radius="0.025" length="0.180"/>
      </geometry>
      <material name="aluminum">
        <color rgba="0.7 0.7 0.7 1"/>
      </material>
    </visual>
    <collision>
      <origin xyz="0 0 0.090" rpy="0 0 0"/>
      <geometry>
        <cylinder radius="0.025" length="0.180"/>
      </geometry>
    </collision>
  </link>
  <link name="arm_right_link_4">
    <inertial>
      <origin xyz="0 0 0.090" rpy="0 0 0"/>
      <mass value="0.120"/>
      <inertia ixx="0.000324" ixy="0" ixz="0" iyy="0.000324" iyz="0" izz="0.000038"/>
    </inertial>
    <visual>
      <origin xyz="0 0 0.090" rpy="0 0 0"/>
      <geometry>
        <cylinder radius="0.025" length="0.180"/>
      </geometry>
      <material name="aluminum">
        <color rgba="0.7 0.7 0.7 1"/>
      </material>
    </visual>
    <collision>
      <origin xyz="0 0 0.090" rpy="0 0 0"/>
      <geometry>
        <cylinder radius="0.025" length="0.180"/>
      </geometry>
    </collision>
  </link>
  <link name="arm_right_link_5">
    <inertial>
      <origin xyz="0 0 0.090" rpy="0 0 0"/>
      <mass value="0.120"/>
      <inertia ixx="0.000324" ixy="0" ixz="0" iyy="0.000324" iyz="0" izz="0.000038"/>
    </inertial>
    <visual>
      <origin xyz="0 0 0.090" rpy="0 0 0"/>
      <geometry>
        <cylinder radius="0.025" length="0.180"/>
      </geometry>
      <material name="aluminum">
        <color rgba="0.7 0.7 0.7 1"/>
      </material>
    </visual>
    <collision>
      <origin xyz="0 0 0.090" rpy="0 0 0"/>
      <geometry>
        <cylinder radius="0.025" length="0.180"/>
      </geometry>
    </collision>
  </link>
  <link name="arm_right_link_6">
    <inertial>
      <origin xyz="0 0 0.090" rpy="0 0 0"/>
      <mass value="0.120"/>
      <inertia ixx="0.000324" ixy="0" ixz="0" iyy="0.000324" iyz="0" izz="0.000038"/>
    </inertial>
    <visual>
      <origin xyz="0 0 0.090" rpy="0 0 0"/>
      <geometry>
        <cylinder radius="0.025" length="0.180"/>
      </geometry>
      <material name="aluminum">
        <color rgba="0.7 0.7 0.7 1"/>
      </material>
    </visual>
    <collision>
      <origin xyz="0 0 0.090" rpy="0 0 0"/>
      <geometry>
        <cylinder radius="0.025" length="0.180"/>
      </geometry>
    </collision>
  </link>
  <link name="arm_right_link_7">
    <inertial>
      <origin xyz="0 0 0.090" rpy="0 0 0"/>
      <mass value="0.120"/>
      <inertia ixx="0.000324" ixy="0" ixz="0" iyy="0.000324" iyz="0" izz="0.000038"/>
    </inertial>
    <visual>
      <origin xyz="0 0 0.090" rpy="0 0 0"/>
      <geometry>
        <cylinder radius="0.025" length="0.180"/>
      </geometry>
      <material name="aluminum">
        <color rgba="0.7 0.7 0.7 1"/>
      </material>
    </visual>
    <collision>
      <origin xyz="0 0 0.090" rpy="0 0 0"/>
      <geometry>
        <cylinder radius="0.025" length="0.180"/>
      </geometry>
    </collision>
  </link>
  <joint name="arm_right_joint_1" type="continuous">
    <origin xyz="0.050 -0.250 0.250" rpy="0 0 0"/>
    <parent link="torso_link"/>
    <child link="arm_right_link_1"/>
    <axis xyz="0 0 1"/>
  </joint>
  <joint name="arm_right_joint_2" type="continuous">
    <origin xyz="0.000 0.000 0.180" rpy="0 0 0"/>
    <parent link="arm_right_link_1"/>
    <child link="arm_right_link_2"/>
    <axis xyz="0 1 0"/>
  </joint>
  <joint name="arm_right_joint_3" type="continuous">
    <origin xyz="0.000 0.000 0.180" rpy="0 0 0"/>
    <parent link="arm_right_link_2"/>
    <child link="arm_right_link_3"/>
    <axis xyz="0 1 0"/>
  </joint>
  <joint name="arm_right_joint_4" type="continuous">
    <origin xyz="0.000 0.000 0.180" rpy="0 0 0"/>
    <parent link="arm_right_link_3"/>
    <child link="arm_right_link_4"/>
    <axis xyz="1 0 0"/>
  </joint>
  <joint name="arm_right_joint_5" type="continuous">
    <origin xyz="0.000 0.000 0.180" rpy="0 0 0"/>
    <parent link="arm_right_link_4"/>
    <child link="arm_right_link_5"/>
    <axis xyz="0 1 0"/>
  </joint>
  <joint name="arm_right_joint_6" type="continuous">
    <origin xyz="0.000 0.000 0.180" rpy="0 0 0"/>
    <parent link="arm_right_link_5"/>
    <child link="arm_right_link_6"/>
    <axis xyz="1 0 0"/>
  </joint>
  <joint name="arm_right_joint_7" type="continuous">
    <origin xyz="0.000 0.000 0.180" rpy="0 0 0"/>
    <parent link="arm_right_link_6"/>
    <child link="arm_right_link_7"/>
    <axis xyz="0 1 0"/>
  </joint>

  <transmission name="trans_leg_right_1">
  <type>transmission_interface/SimpleTransmission</type>
  <actuator name="motor_leg_right_1">
    <hardwareInterface>hardware_interface/EffortJointInterface</hardwareInterface>
    <mechanicalReduction>1</mechanicalReduction>
  </actuator>
  <joint name="leg_right_joint_1">
    <hardwareInterface>hardware_interface/EffortJointInterface</hardwareInterface>
  </joint>
  </transmission>

  <transmission name="trans_leg_right_2">
  <type>transmission_interface/SimpleTransmission</type>
  <actuator name="motor_leg_right_2">
    <hardwareInterface>hardware_interface/EffortJointInterface</hardwareInterface>
    <mechanicalReduction>1</mechanicalReduction>
  </actuator>
  <joint name="leg_right_joint_2">
    <hardwareInterface>hardware_interface/EffortJointInterface</hardwareInterface>
  </joint>
  </transmission>

  <transmission name="trans_leg_right_3">
  <type>transmission_interface/SimpleTransmission</type>
  <actuator name="motor_leg_right_3">
    <hardwareInterface>hardware_interface/EffortJointInterface</hardwareInterface>
    <mechanicalReduction>1</mechanicalReduction>
  </actuator>
  <joint name="leg_right_joint_3">
    <hardwareInterface>hardware_interface/EffortJointInterface</hardwareInterface>
  </joint>
  </transmission>

  <transmission name="trans_leg_right_4">
  <type>transmission_interface/SimpleTransmission</type>
  <actuator name="motor_leg_right_4">
    <hardwareInterface>hardware_interface/EffortJointInterface</hardwareInterface>
    <mechanicalReduction>1</mechanicalReduction>
  </actuator>
  <joint name="leg_right_joint_4">
    <hardwareInterface>hardware_interface/EffortJointInterface</hardwareInterface>
  </joint>
  </transmission>

  <transmission name="trans_leg_right_5">
  <type>transmission_interface/SimpleTransmission</type>
  <actuator name="motor_leg_right_5">
    <hardwareInterface>hardware_interface/EffortJointInterface</hardwareInterface>
    <mechanicalReduction>1</mechanicalReduction>
  </actuator>
  <joint name="leg_right_joint_5">
    <hardwareInterface>hardware_interface/EffortJointInterface</hardwareInterface>
  </joint>
  </transmission>

  <transmission name="trans_leg_right_6">
  <type>transmission_interface/SimpleTransmission</type>
  <actuator name="motor_leg_right_6">
    <hardwareInterface>hardware_interface/EffortJointInterface</hardwareInterface>
    <mechanicalReduction>1</mechanicalReduction>
  </actuator>
  <joint name="leg_right_joint_6">
    <hardwareInterface>hardware_interface/EffortJointInterface</hardwareInterface>
  </joint>
  </transmission>

  <transmission name="trans_leg_right_7">
  <type>transmission_interface/SimpleTransmission</type>
  <actuator name="motor_leg_right_7">
    <hardwareInterface>hardware_interface/EffortJointInterface</hardwareInterface>
    <mechanicalReduction>1</mechanicalReduction>
  </actuator>
  <joint name="leg_right_joint_7">
    <hardwareInterface>hardware_interface/EffortJointInterface</hardwareInterface>
  </joint>
  </transmission>
  </xacro:if>
  <xacro:if value="${enable_leg_left}">
  <link
    name="leg_left_link_1">
    <inertial>
      <origin
        xyz="-0.00382422792815949 -0.0123142355221975 0.0766747228132015"
        rpy="0 0 0" />
      <mass
        value="0.292899916417866" />
      <inertia
        ixx="0.000252199489311626"
        ixy="1.84502350325129E-05"
        ixz="3.06532558789357E-06"
        iyy="0.000305653266020346"
        iyz="9.64612915614931E-06"
        izz="0.000181236852257132" />
    </inertial>
    <visual>
      <origin
        xyz="0 0 0"
        rpy="0 0 0" />
      <geometry>
        <mesh
          filename="package://wanren_arm/meshes/leg_r1.STL" />
      </geometry>
      <material
        name="">
        <color
          rgba="1 1 1 1" />
      </material>
    </visual>
    <collision>
      <origin
        xyz="0 0 0"
        rpy="0 0 0" />
      <geometry>
        <mesh
          filename="package://wanren_arm/meshes/leg_r1.STL" />
      </geometry>
    </collision>
  </link>
  <joint
    name="leg_left_joint_1"
    type="continuous">
    <origin
      xyz="1 1 -0.011999999999999"
      rpy="0 0 0" />
    <parent
      link="torso_link" />
    <child
      link="leg_left_link_1" />
    <axis
      xyz="0 0 -1" />
  </joint>
  <link
    name="leg_left_link_2">
    <inertial>
      <origin
        xyz="0.0284932164900757 0.0852314382000906 0.0233442478183801"
        rpy="0 0 0" />
      <mass
        value="0.118782011304387" />
      <inertia
        ixx="0.000148335029284927"
        ixy="-8.65175116738488E-06"
        ixz="-1.27967801985177E-05"
        iyy="0.000134918605784322"
        iyz="-4.16906433393106E-05"
        izz="0.000154509301437256" />
    </inertial>
    <visual>
      <origin
        xyz="0 0 0"
        rpy="0 0 0" />
      <geometry>
        <mesh
          filename="package://wanren_arm/meshes/leg_r2.STL" />
      </geometry>
      <material
        name="">
        <color
          rgba="1 1 1 1" />
      </material>
    </visual>
    <collision>
      <origin
        xyz="0 0 0"
        rpy="0 0 0" />
      <geometry>
        <mesh
          filename="package://wanren_arm/meshes/leg_r2.STL" />
      </geometry>
    </collision>
  </link>
  <joint
    name="leg_left_joint_2"
    type="continuous">
    <origin
      xyz="-0.0136812977041495 -0.0436944371355362 0.0808116620061236"
      rpy="0 0 0" />
    <parent
      link="leg_left_link_1" />
    <child
      link="leg_left_link_2" />
    <axis
      xyz="0.29752487908452 0.954714065218347 0" />
  </joint>
  <link
    name="leg_left_link_3">
    <inertial>
      <origin
        xyz="0.00440804925886197 -0.000927955750798931 0.0105438054247052"
        rpy="0 0 0" />
      <mass
        value="0.395227613542105" />
      <inertia
        ixx="0.000308890320718613"
        ixy="-5.97376048863321E-06"
        ixz="-4.28271122717806E-07"
        iyy="0.000290511069752979"
        iyz="-7.01321630599807E-06"
        izz="0.000217174460223541" />
    </inertial>
    <visual>
      <origin
        xyz="0 0 0"
        rpy="0 0 0" />
      <geometry>
        <mesh
          filename="package://wanren_arm/meshes/leg_r3.STL" />
      </geometry>
      <material
        name="">
        <color
          rgba="0.752941176470588 0.752941176470588 0.752941176470588 1" />
      </material>
    </visual>
    <collision>
      <origin
        xyz="0 0 0"
        rpy="0 0 0" />
      <geometry>
        <mesh
          filename="package://wanren_arm/meshes/leg_r3.STL" />
      </geometry>
    </collision>
  </link>
  <joint
    name="leg_left_joint_3"
    type="continuous">
    <origin
      xyz="0.0412068272569313 0.104588881771451 0.106228185949221"
      rpy="0 0 0" />
    <parent
      link="leg_left_link_2" />
    <child
      link="leg_left_link_3" />
    <axis
      xyz="-0.0722349306802614 0.022511126419206 -0.997133573788866" />
  </joint>
  <link
    name="leg_left_link_4">
    <inertial>
      <origin
        xyz="0.0155060558890136 0.0411774297341984 0.0346709586399187"
        rpy="0 0 0" />
      <mass
        value="0.0222841339329651" />
      <inertia
        ixx="1.84809601603307E-05"
        ixy="-7.49503824125524E-07"
        ixz="7.29303214418526E-07"
        iyy="1.42244264185631E-05"
        iyz="5.6744596945616E-06"
        izz="8.89285098125665E-06" />
    </inertial>
    <visual>
      <origin
        xyz="0 0 0"
        rpy="0 0 0" />
      <geometry>
        <mesh
          filename="package://wanren_arm/meshes/leg_r4.STL" />
      </geometry>
      <material
        name="">
        <color
          rgba="1 1 1 1" />
      </material>
    </visual>
    <collision>
      <origin
        xyz="0 0 0"
        rpy="0 0 0" />
      <geometry>
        <mesh
          filename="package://wanren_arm/meshes/leg_r4.STL" />
      </geometry>
    </collision>
  </link>
  <joint
    name="leg_left_joint_4"
    type="continuous">
    <origin
      xyz="-0.00228042956033238 -0.0297792321778995 0.0833604475054363"
      rpy="0 0 0" />
    <parent
      link="leg_left_link_3" />
    <child
      link="leg_left_link_4" />
    <axis
      xyz="0.282983296167026 0.959124144572578 0.0011529910516605" />
  </joint>
  <link
    name="leg_left_link_5">
    <inertial>
      <origin
        xyz="-0.0048559147531092 -0.0119363039004067 -0.00678188706287566"
        rpy="0 0 0" />
      <mass
        value="0.38824624930896" />
      <inertia
        ixx="0.000237526648339387"
        ixy="-5.31429070295641E-05"
        ixz="2.19325891659962E-05"
        iyy="0.000363875907133575"
        iyz="1.18765086359219E-05"
        izz="0.000378463701930693" />
    </inertial>
    <visual>
      <origin
        xyz="0 0 0"
        rpy="0 0 0" />
      <geometry>
        <mesh
          filename="package://wanren_arm/meshes/leg_r5.STL" />
      </geometry>
      <material
        name="">
        <color
          rgba="0.752941176470588 0.752941176470588 0.752941176470588 1" />
      </material>
    </visual>
    <collision>
      <origin
        xyz="0 0 0"
        rpy="0 0 0" />
      <geometry>
        <mesh
          filename="package://wanren_arm/meshes/leg_r5.STL" />
      </geometry>
    </collision>
  </link>
  <joint
    name="leg_left_joint_5"
    type="continuous">
    <origin
      xyz="0.0181511434262854 0.025007599076044 0.111134888878763"
      rpy="0 1.26722046551249 0" />
    <parent
      link="leg_left_link_4" />
    <child
      link="leg_left_link_5" />
    <axis
      xyz="0.923719785557326 0.0273056458564005 -0.382094437900229" />
  </joint>
  <link
    name="leg_left_link_6">
    <inertial>
      <origin
        xyz="0.0651691107467127 0.0806102275858783 -0.0545046281847596"
        rpy="0 0 0" />
      <mass
        value="0.174871084341935" />
      <inertia
        ixx="0.000144391761957596"
        ixy="-1.80182197600083E-05"
        ixz="1.3262109156489E-05"
        iyy="7.06944905975503E-05"
        iyz="1.59148040690902E-05"
        izz="0.000136401918690474" />
    </inertial>
    <visual>
      <origin
        xyz="0 0 0"
        rpy="0 0 0" />
      <geometry>
        <mesh
          filename="package://wanren_arm/meshes/leg_r6.STL" />
      </geometry>
      <material
        name="">
        <color
          rgba="1 1 1 1" />
      </material>
    </visual>
    <collision>
      <origin
        xyz="0 0 0"
        rpy="0 0 0" />
      <geometry>
        <mesh
          filename="package://wanren_arm/meshes/leg_r6.STL" />
      </geometry>
    </collision>
  </link>
  <joint
    name="leg_left_joint_6"
    type="continuous">
    <origin
      xyz="-0.0550712045826083 -0.0332459772838745 -0.000878918231283499"
      rpy="1.5372364468678 -1.26722046551249 0" />
    <parent
      link="leg_left_link_5" />
    <child
      link="leg_left_link_6" />
    <axis
      xyz="0.565655964466871 0 -0.824641334073823" />
  </joint>
  <link
    name="leg_left_link_7">
    <inertial>
      <origin
        xyz="0.122014637753753 -0.108460665221082 -0.0505526819127103"
        rpy="0 0 0" />
      <mass
        value="0.784412251530751" />
      <inertia
        ixx="0.00035684591190941"
        ixy="5.28938521033195E-05"
        ixz="1.61063033449861E-05"
        iyy="0.000393694186319801"
        iyz="-3.02303341596539E-06"
        izz="0.000403461621026228" />
    </inertial>
    <visual>
      <origin xyz="0 0 0" rpy="0 0 0"/>
  	<geometry>
    	<box size="0.1 0.05 0.04"/>
  	</geometry>
    </visual>
    <collision>
  	<origin xyz="0 0 0" rpy="0 0 0"/>
  	<geometry>
    	<box size="0.1 0.05 0.04"/>
  	</geometry>
    </collision>
  </link>
  <joint
    name="leg_left_joint_7"
    type="continuous">
    <origin
      xyz="0.0506954674848457 0.0975609362242854 -0.0679978120533321"
      rpy="-1.5372364468678 0 0" />
    <parent
      link="leg_left_link_6" />
    <child
      link="leg_left_link_7" />
    <axis
      xyz="0.804819794366103 -0.559061164385712 -0.199288015375224" />
  </joint>

  <transmission name="trans_leg_left_1">
  <type>transmission_interface/SimpleTransmission</type>
  <actuator name="motor_leg_left_1">
    <hardwareInterface>hardware_interface/EffortJointInterface</hardwareInterface>
    <mechanicalReduction>1</mechanicalReduction>
  </actuator>
  <joint name="leg_left_joint_1">
    <hardwareInterface>hardware_interface/EffortJointInterface</hardwareInterface>
  </joint>
  </transmission>

  <transmission name="trans_leg_left_2">
  <type>transmission_interface/SimpleTransmission</type>
  <actuator name="motor_leg_left_2">
    <hardwareInterface>hardware_interface/EffortJointInterface</hardwareInterface>
    <mechanicalReduction>1</mechanicalReduction>
  </actuator>
  <joint name="leg_left_joint_2">
    <hardwareInterface>hardware_interface/EffortJointInterface</hardwareInterface>
  </joint>
  </transmission>

  <transmission name="trans_leg_left_3">
  <type>transmission_interface/SimpleTransmission</type>
  <actuator name="motor_leg_left_3">
    <hardwareInterface>hardware_interface/EffortJointInterface</hardwareInterface>
    <mechanicalReduction>1</mechanicalReduction>
  </actuator>
  <joint name="leg_left_joint_3">
    <hardwareInterface>hardware_interface/EffortJointInterface</hardwareInterface>
  </joint>
  </transmission>

  <transmission name="trans_leg_left_4">
  <type>transmission_interface/SimpleTransmission</type>
  <actuator name="motor_leg_left_4">
    <hardwareInterface>hardware_interface/EffortJointInterface</hardwareInterface>
    <mechanicalReduction>1</mechanicalReduction>
  </actuator>
  <joint name="leg_left_joint_4">
    <hardwareInterface>hardware_interface/EffortJointInterface</hardwareInterface>
  </joint>
  </transmission>

  <transmission name="trans_leg_left_5">
  <type>transmission_interface/SimpleTransmission</type>
  <actuator name="motor_leg_left_5">
    <hardwareInterface>hardware_interface/EffortJointInterface</hardwareInterface>
    <mechanicalReduction>1</mechanicalReduction>
  </actuator>
  <joint name="leg_left_joint_5">
    <hardwareInterface>hardware_interface/EffortJointInterface</hardwareInterface>
  </joint>
  </transmission>

  <transmission name="trans_leg_left_6">
  <type>transmission_interface/SimpleTransmission</type>
  <actuator name="motor_leg_left_6">
    <hardwareInterface>hardware_interface/EffortJointInterface</hardwareInterface>
    <mechanicalReduction>1</mechanicalReduction>
  </actuator>
  <joint name="leg_left_joint_6">
    <hardwareInterface>hardware_interface/EffortJointInterface</hardwareInterface>
  </joint>
  </transmission>

  <transmission name="trans_leg_left_7">
  <type>transmission_interface/SimpleTransmission</type>
  <actuator name="motor_leg_left_7">
    <hardwareInterface>hardware_interface/EffortJointInterface</hardwareInterface>
    <mechanicalReduction>1</mechanicalReduction>
  </actuator>
  <joint name="leg_left_joint_7">
    <hardwareInterface>hardware_interface/EffortJointInterface</hardwareInterface>
  </joint>
  </transmission>

  </xacro:if>

  <transmission name="trans_neck_left_joint_1">
  <type>transmission_interface/SimpleTransmission</type>
  <actuator name="motor_neck_left_joint_1">
    <hardwareInterface>hardware_interface/EffortJointInterface</hardwareInterface>
    <mechanicalReduction>1</mechanicalReduction>
  </actuator>
  <joint name="neck_left_joint_1">
    <hardwareInterface>hardware_interface/EffortJointInterface</hardwareInterface>
  </joint>
  </transmission>

  <transmission name="trans_neck_left_joint_2">
  <type>transmission_interface/SimpleTransmission</type>
  <actuator name="motor_neck_left_joint_2">
    <hardwareInterface>hardware_interface/EffortJointInterface</hardwareInterface>
    <mechanicalReduction>1</mechanicalReduction>
  </actuator>
  <joint name="neck_left_joint_2">
    <hardwareInterface>hardware_interface/EffortJointInterface</hardwareInterface>
  </joint>
  </transmission>

  <transmission name="trans_neck_left_joint_3">
  <type>transmission_interface/SimpleTransmission</type>
  <actuator name="motor_neck_left_joint_3">
    <hardwareInterface>hardware_interface/EffortJointInterface</hardwareInterface>
    <mechanicalReduction>1</mechanicalReduction>
  </actuator>
  <joint name="neck_left_joint_3">
    <hardwareInterface>hardware_interface/EffortJointInterface</hardwareInterface>
  </joint>
  </transmission>

  <transmission name="trans_neck_left_joint_4">
  <type>transmission_interface/SimpleTransmission</type>
  <actuator name="motor_neck_left_joint_4">
    <hardwareInterface>hardware_interface/EffortJointInterface</hardwareInterface>
    <mechanicalReduction>1</mechanicalReduction>
  </actuator>
  <joint name="neck_left_joint_4">
    <hardwareInterface>hardware_interface/EffortJointInterface</hardwareInterface>
  </joint>
  </transmission>

  <transmission name="trans_neck_left_joint_5">
  <type>transmission_interface/SimpleTransmission</type>
  <actuator name="motor_neck_left_joint_5">
    <hardwareInterface>hardware_interface/EffortJointInterface</hardwareInterface>
    <mechanicalReduction>1</mechanicalReduction>
  </actuator>
  <joint name="neck_left_joint_5">
    <hardwareInterface>hardware_interface/EffortJointInterface</hardwareInterface>
  </joint>
  </transmission>

  <transmission name="trans_neck_left_joint_6">
  <type>transmission_interface/SimpleTransmission</type>
  <actuator name="motor_neck_left_joint_6">
    <hardwareInterface>hardware_interface/EffortJointInterface</hardwareInterface>
    <mechanicalReduction>1</mechanicalReduction>
  </actuator>
  <joint name="neck_left_joint_6">
    <hardwareInterface>hardware_interface/EffortJointInterface</hardwareInterface>
  </joint>
  </transmission>

  <transmission name="trans_neck_left_joint_7">
  <type>transmission_interface/SimpleTransmission</type>
  <actuator name="motor_neck_left_joint_7">
    <hardwareInterface>hardware_interface/EffortJointInterface</hardwareInterface>
    <mechanicalReduction>1</mechanicalReduction>
  </actuator>
  <joint name="neck_left_joint_7">
    <hardwareInterface>hardware_interface/EffortJointInterface</hardwareInterface>
  </joint>
  </transmission>

  </xacro:if>

  <transmission name="trans_neck_right_joint_1">
  <type>transmission_interface/SimpleTransmission</type>
  <actuator name="motor_neck_right_joint_1">
    <hardwareInterface>hardware_interface/EffortJointInterface</hardwareInterface>
    <mechanicalReduction>1</mechanicalReduction>
  </actuator>
  <joint name="neck_right_joint_1">
    <hardwareInterface>hardware_interface/EffortJointInterface</hardwareInterface>
  </joint>
  </transmission>

  <transmission name="trans_neck_right_joint_2">
  <type>transmission_interface/SimpleTransmission</type>
  <actuator name="motor_neck_right_joint_2">
    <hardwareInterface>hardware_interface/EffortJointInterface</hardwareInterface>
    <mechanicalReduction>1</mechanicalReduction>
  </actuator>
  <joint name="neck_right_joint_2">
    <hardwareInterface>hardware_interface/EffortJointInterface</hardwareInterface>
  </joint>
  </transmission>

  <transmission name="trans_neck_right_joint_3">
  <type>transmission_interface/SimpleTransmission</type>
  <actuator name="motor_neck_right_joint_3">
    <hardwareInterface>hardware_interface/EffortJointInterface</hardwareInterface>
    <mechanicalReduction>1</mechanicalReduction>
  </actuator>
  <joint name="neck_right_joint_3">
    <hardwareInterface>hardware_interface/EffortJointInterface</hardwareInterface>
  </joint>
  </transmission>

  <transmission name="trans_neck_right_joint_4">
  <type>transmission_interface/SimpleTransmission</type>
  <actuator name="motor_neck_right_joint_4">
    <hardwareInterface>hardware_interface/EffortJointInterface</hardwareInterface>
    <mechanicalReduction>1</mechanicalReduction>
  </actuator>
  <joint name="neck_right_joint_4">
    <hardwareInterface>hardware_interface/EffortJointInterface</hardwareInterface>
  </joint>
  </transmission>

  <transmission name="trans_neck_right_joint_5">
  <type>transmission_interface/SimpleTransmission</type>
  <actuator name="motor_neck_right_joint_5">
    <hardwareInterface>hardware_interface/EffortJointInterface</hardwareInterface>
    <mechanicalReduction>1</mechanicalReduction>
  </actuator>
  <joint name="neck_right_joint_5">
    <hardwareInterface>hardware_interface/EffortJointInterface</hardwareInterface>
  </joint>
  </transmission>

  <transmission name="trans_neck_right_joint_6">
  <type>transmission_interface/SimpleTransmission</type>
  <actuator name="motor_neck_right_joint_6">
    <hardwareInterface>hardware_interface/EffortJointInterface</hardwareInterface>
    <mechanicalReduction>1</mechanicalReduction>
  </actuator>
  <joint name="neck_right_joint_6">
    <hardwareInterface>hardware_interface/EffortJointInterface</hardwareInterface>
  </joint>
  </transmission>

  <transmission name="trans_neck_right_joint_7">
  <type>transmission_interface/SimpleTransmission</type>
  <actuator name="motor_neck_right_joint_7">
    <hardwareInterface>hardware_interface/EffortJointInterface</hardwareInterface>
    <mechanicalReduction>1</mechanicalReduction>
  </actuator>
  <joint name="neck_right_joint_7">
    <hardwareInterface>hardware_interface/EffortJointInterface</hardwareInterface>
  </joint>
  </transmission>

  </xacro:if>

  </xacro:if>

  <transmission name="trans_arm_left_joint_1">
  <type>transmission_interface/SimpleTransmission</type>
  <actuator name="motor_arm_left_joint_1">
    <hardwareInterface>hardware_interface/EffortJointInterface</hardwareInterface>
    <mechanicalReduction>1</mechanicalReduction>
  </actuator>
  <joint name="arm_left_joint_1">
    <hardwareInterface>hardware_interface/EffortJointInterface</hardwareInterface>
  </joint>
  </transmission>

  <transmission name="trans_arm_left_joint_2">
  <type>transmission_interface/SimpleTransmission</type>
  <actuator name="motor_arm_left_joint_2">
    <hardwareInterface>hardware_interface/EffortJointInterface</hardwareInterface>
    <mechanicalReduction>1</mechanicalReduction>
  </actuator>
  <joint name="arm_left_joint_2">
    <hardwareInterface>hardware_interface/EffortJointInterface</hardwareInterface>
  </joint>
  </transmission>

  <transmission name="trans_arm_left_joint_3">
  <type>transmission_interface/SimpleTransmission</type>
  <actuator name="motor_arm_left_joint_3">
    <hardwareInterface>hardware_interface/EffortJointInterface</hardwareInterface>
    <mechanicalReduction>1</mechanicalReduction>
  </actuator>
  <joint name="arm_left_joint_3">
    <hardwareInterface>hardware_interface/EffortJointInterface</hardwareInterface>
  </joint>
  </transmission>

  <transmission name="trans_arm_left_joint_4">
  <type>transmission_interface/SimpleTransmission</type>
  <actuator name="motor_arm_left_joint_4">
    <hardwareInterface>hardware_interface/EffortJointInterface</hardwareInterface>
    <mechanicalReduction>1</mechanicalReduction>
  </actuator>
  <joint name="arm_left_joint_4">
    <hardwareInterface>hardware_interface/EffortJointInterface</hardwareInterface>
  </joint>
  </transmission>

  <transmission name="trans_arm_left_joint_5">
  <type>transmission_interface/SimpleTransmission</type>
  <actuator name="motor_arm_left_joint_5">
    <hardwareInterface>hardware_interface/EffortJointInterface</hardwareInterface>
    <mechanicalReduction>1</mechanicalReduction>
  </actuator>
  <joint name="arm_left_joint_5">
    <hardwareInterface>hardware_interface/EffortJointInterface</hardwareInterface>
  </joint>
  </transmission>

  <transmission name="trans_arm_left_joint_6">
  <type>transmission_interface/SimpleTransmission</type>
  <actuator name="motor_arm_left_joint_6">
    <hardwareInterface>hardware_interface/EffortJointInterface</hardwareInterface>
    <mechanicalReduction>1</mechanicalReduction>
  </actuator>
  <joint name="arm_left_joint_6">
    <hardwareInterface>hardware_interface/EffortJointInterface</hardwareInterface>
  </joint>
  </transmission>

  <transmission name="trans_arm_left_joint_7">
  <type>transmission_interface/SimpleTransmission</type>
  <actuator name="motor_arm_left_joint_7">
    <hardwareInterface>hardware_interface/EffortJointInterface</hardwareInterface>
    <mechanicalReduction>1</mechanicalReduction>
  </actuator>
  <joint name="arm_left_joint_7">
    <hardwareInterface>hardware_interface/EffortJointInterface</hardwareInterface>
  </joint>
  </transmission>

  </xacro:if>

  <transmission name="trans_arm_right_joint_1">
  <type>transmission_interface/SimpleTransmission</type>
  <actuator name="motor_arm_right_joint_1">
    <hardwareInterface>hardware_interface/EffortJointInterface</hardwareInterface>
    <mechanicalReduction>1</mechanicalReduction>
  </actuator>
  <joint name="arm_right_joint_1">
    <hardwareInterface>hardware_interface/EffortJointInterface</hardwareInterface>
  </joint>
  </transmission>

  <transmission name="trans_arm_right_joint_2">
  <type>transmission_interface/SimpleTransmission</type>
  <actuator name="motor_arm_right_joint_2">
    <hardwareInterface>hardware_interface/EffortJointInterface</hardwareInterface>
    <mechanicalReduction>1</mechanicalReduction>
  </actuator>
  <joint name="arm_right_joint_2">
    <hardwareInterface>hardware_interface/EffortJointInterface</hardwareInterface>
  </joint>
  </transmission>

  <transmission name="trans_arm_right_joint_3">
  <type>transmission_interface/SimpleTransmission</type>
  <actuator name="motor_arm_right_joint_3">
    <hardwareInterface>hardware_interface/EffortJointInterface</hardwareInterface>
    <mechanicalReduction>1</mechanicalReduction>
  </actuator>
  <joint name="arm_right_joint_3">
    <hardwareInterface>hardware_interface/EffortJointInterface</hardwareInterface>
  </joint>
  </transmission>

  <transmission name="trans_arm_right_joint_4">
  <type>transmission_interface/SimpleTransmission</type>
  <actuator name="motor_arm_right_joint_4">
    <hardwareInterface>hardware_interface/EffortJointInterface</hardwareInterface>
    <mechanicalReduction>1</mechanicalReduction>
  </actuator>
  <joint name="arm_right_joint_4">
    <hardwareInterface>hardware_interface/EffortJointInterface</hardwareInterface>
  </joint>
  </transmission>

  <transmission name="trans_arm_right_joint_5">
  <type>transmission_interface/SimpleTransmission</type>
  <actuator name="motor_arm_right_joint_5">
    <hardwareInterface>hardware_interface/EffortJointInterface</hardwareInterface>
    <mechanicalReduction>1</mechanicalReduction>
  </actuator>
  <joint name="arm_right_joint_5">
    <hardwareInterface>hardware_interface/EffortJointInterface</hardwareInterface>
  </joint>
  </transmission>

  <transmission name="trans_arm_right_joint_6">
  <type>transmission_interface/SimpleTransmission</type>
  <actuator name="motor_arm_right_joint_6">
    <hardwareInterface>hardware_interface/EffortJointInterface</hardwareInterface>
    <mechanicalReduction>1</mechanicalReduction>
  </actuator>
  <joint name="arm_right_joint_6">
    <hardwareInterface>hardware_interface/EffortJointInterface</hardwareInterface>
  </joint>
  </transmission>

  <transmission name="trans_arm_right_joint_7">
  <type>transmission_interface/SimpleTransmission</type>
  <actuator name="motor_arm_right_joint_7">
    <hardwareInterface>hardware_interface/EffortJointInterface</hardwareInterface>
    <mechanicalReduction>1</mechanicalReduction>
  </actuator>
  <joint name="arm_right_joint_7">
    <hardwareInterface>hardware_interface/EffortJointInterface</hardwareInterface>
  </joint>
  </transmission>

  </xacro:if>

  <xacro:if value="${enable_waist}">
  <transmission name="trans_waist_yaw_joint">
  <type>transmission_interface/SimpleTransmission</type>
  <actuator name="motor_waist_yaw_joint">
    <hardwareInterface>hardware_interface/EffortJointInterface</hardwareInterface>
    <mechanicalReduction>1</mechanicalReduction>
  </actuator>
  <joint name="waist_yaw_joint">
    <hardwareInterface>hardware_interface/EffortJointInterface</hardwareInterface>
  </joint>
  </transmission>
  </xacro:if>


</robot>
